WARNING 2024-12-29 12:16:45,776 Forbidden: /accounts/users/me/get-myname/
WARNING 2024-12-29 12:16:45,776 Forbidden: /accounts/users/me/get-myname/
WARNING 2024-12-29 12:17:47,728 Not Found: /favicon.ico
WARNING 2024-12-29 12:17:47,728 Not Found: /favicon.ico
WARNING 2024-12-29 12:18:02,190 Forbidden: /accounts/users/me/get-myname/
WARNING 2024-12-29 12:18:02,190 Forbidden: /accounts/users/me/get-myname/
WARNING 2024-12-29 12:25:35,248 Forbidden: /accounts/users/me/get-myname/
WARNING 2024-12-29 12:25:35,248 Forbidden: /accounts/users/me/get-myname/
WARNING 2024-12-29 12:25:38,057 Forbidden: /accounts/users/me/get-myname/
WARNING 2024-12-29 12:25:38,057 Forbidden: /accounts/users/me/get-myname/
WARNING 2024-12-29 12:25:38,062 Not Found: /favicon.ico
WARNING 2024-12-29 12:25:38,062 Not Found: /favicon.ico
WARNING 2024-12-29 12:25:38,875 Forbidden: /accounts/users/me/get-myname/
WARNING 2024-12-29 12:25:38,875 Forbidden: /accounts/users/me/get-myname/
WARNING 2024-12-29 12:26:48,411 Forbidden: /accounts/users/me/get-myname/
WARNING 2024-12-29 12:26:48,411 Forbidden: /accounts/users/me/get-myname/
WARNING 2024-12-29 12:31:58,206 Not Found: /favicon.ico
WARNING 2024-12-29 12:31:58,206 Not Found: /favicon.ico
WARNING 2024-12-29 13:14:41,192 Forbidden: /accounts/users/me/get-myname/
WARNING 2024-12-29 13:14:41,192 Forbidden: /accounts/users/me/get-myname/
WARNING 2024-12-29 13:14:41,927 Forbidden: /accounts/users/me/get-myname/
WARNING 2024-12-29 13:14:41,927 Forbidden: /accounts/users/me/get-myname/
WARNING 2024-12-29 13:14:47,647 Forbidden: /accounts/users/me/get-myname/
WARNING 2024-12-29 13:14:47,647 Forbidden: /accounts/users/me/get-myname/
WARNING 2024-12-29 13:15:07,733 Not Found: /favicon.ico
WARNING 2024-12-29 13:15:07,733 Not Found: /favicon.ico
WARNING 2024-12-29 13:25:53,987 Forbidden: /accounts/users/me/get-myname/
WARNING 2024-12-29 13:25:53,987 Forbidden: /accounts/users/me/get-myname/
WARNING 2024-12-29 13:26:03,456 Forbidden: /accounts/users/me/get-myname/
WARNING 2024-12-29 13:26:03,456 Forbidden: /accounts/users/me/get-myname/
WARNING 2024-12-29 13:26:11,845 Forbidden: /accounts/users/me/get-myname/
WARNING 2024-12-29 13:26:11,845 Forbidden: /accounts/users/me/get-myname/
WARNING 2024-12-29 13:26:24,474 Forbidden: /accounts/users/me/get-myname/
WARNING 2024-12-29 13:26:24,474 Forbidden: /accounts/users/me/get-myname/
WARNING 2024-12-29 13:26:40,160 Forbidden: /accounts/users/me/get-myname/
WARNING 2024-12-29 13:26:40,160 Forbidden: /accounts/users/me/get-myname/
WARNING 2024-12-29 13:27:04,560 Forbidden: /accounts/users/me/get-myname/
WARNING 2024-12-29 13:27:04,560 Forbidden: /accounts/users/me/get-myname/
WARNING 2024-12-29 13:27:15,303 Forbidden: /accounts/users/me/get-myname/
WARNING 2024-12-29 13:27:15,303 Forbidden: /accounts/users/me/get-myname/
WARNING 2024-12-29 13:27:28,042 Forbidden: /accounts/users/me/get-myname/
WARNING 2024-12-29 13:27:28,042 Forbidden: /accounts/users/me/get-myname/
WARNING 2024-12-29 13:27:49,582 Forbidden: /accounts/users/me/get-myname/
WARNING 2024-12-29 13:27:49,582 Forbidden: /accounts/users/me/get-myname/
WARNING 2024-12-29 13:28:02,220 Forbidden: /accounts/users/me/get-myname/
WARNING 2024-12-29 13:28:02,220 Forbidden: /accounts/users/me/get-myname/
WARNING 2024-12-29 13:28:29,445 Forbidden: /accounts/users/me/get-myname/
WARNING 2024-12-29 13:28:29,445 Forbidden: /accounts/users/me/get-myname/
WARNING 2024-12-29 13:28:42,787 Forbidden: /accounts/users/me/get-myname/
WARNING 2024-12-29 13:28:42,787 Forbidden: /accounts/users/me/get-myname/
WARNING 2024-12-29 13:29:50,821 Forbidden: /accounts/users/me/get-myname/
WARNING 2024-12-29 13:29:50,821 Forbidden: /accounts/users/me/get-myname/
WARNING 2024-12-29 13:30:24,887 Forbidden: /accounts/users/me/get-myname/
WARNING 2024-12-29 13:30:24,887 Forbidden: /accounts/users/me/get-myname/
WARNING 2024-12-29 13:30:40,490 Forbidden: /accounts/users/me/get-myname/
WARNING 2024-12-29 13:30:40,490 Forbidden: /accounts/users/me/get-myname/
WARNING 2024-12-29 13:30:54,038 Forbidden: /accounts/users/me/get-myname/
WARNING 2024-12-29 13:30:54,038 Forbidden: /accounts/users/me/get-myname/
WARNING 2024-12-29 13:31:29,155 Forbidden: /accounts/users/me/get-myname/
WARNING 2024-12-29 13:31:29,155 Forbidden: /accounts/users/me/get-myname/
WARNING 2024-12-29 13:31:40,969 Forbidden: /accounts/users/me/get-myname/
WARNING 2024-12-29 13:31:40,969 Forbidden: /accounts/users/me/get-myname/
WARNING 2024-12-29 13:33:46,929 Forbidden: /accounts/users/me/get-myname/
WARNING 2024-12-29 13:33:46,929 Forbidden: /accounts/users/me/get-myname/
WARNING 2024-12-29 13:37:39,241 Forbidden: /accounts/users/me/get-myname/
WARNING 2024-12-29 13:37:39,241 Forbidden: /accounts/users/me/get-myname/
WARNING 2024-12-29 13:38:10,829 Forbidden: /accounts/users/me/get-myname/
WARNING 2024-12-29 13:38:10,829 Forbidden: /accounts/users/me/get-myname/
WARNING 2024-12-29 13:38:40,229 Forbidden: /accounts/users/me/get-myname/
WARNING 2024-12-29 13:38:40,229 Forbidden: /accounts/users/me/get-myname/
WARNING 2024-12-29 13:38:51,393 Forbidden: /accounts/users/me/get-myname/
WARNING 2024-12-29 13:38:51,393 Forbidden: /accounts/users/me/get-myname/
WARNING 2024-12-29 13:39:20,155 Forbidden: /accounts/users/me/get-myname/
WARNING 2024-12-29 13:39:20,155 Forbidden: /accounts/users/me/get-myname/
WARNING 2024-12-29 13:39:24,882 Forbidden: /accounts/users/me/get-myname/
WARNING 2024-12-29 13:39:24,882 Forbidden: /accounts/users/me/get-myname/
WARNING 2024-12-29 13:39:24,895 Not Found: /favicon.ico
WARNING 2024-12-29 13:39:24,895 Not Found: /favicon.ico
WARNING 2024-12-29 13:39:48,727 Forbidden: /accounts/users/me/get-myname/
WARNING 2024-12-29 13:39:48,727 Forbidden: /accounts/users/me/get-myname/
WARNING 2024-12-29 13:39:58,093 Forbidden: /accounts/users/me/get-myname/
WARNING 2024-12-29 13:39:58,093 Forbidden: /accounts/users/me/get-myname/
WARNING 2024-12-29 13:42:15,554 Forbidden: /accounts/users/me/get-myname/
WARNING 2024-12-29 13:42:15,554 Forbidden: /accounts/users/me/get-myname/
WARNING 2024-12-29 13:42:17,881 Forbidden: /accounts/users/me/get-myname/
WARNING 2024-12-29 13:42:17,881 Forbidden: /accounts/users/me/get-myname/
WARNING 2024-12-29 13:43:14,775 Forbidden: /accounts/users/me/get-myname/
WARNING 2024-12-29 13:43:14,775 Forbidden: /accounts/users/me/get-myname/
WARNING 2024-12-29 13:43:26,334 Forbidden: /accounts/users/me/get-myname/
WARNING 2024-12-29 13:43:26,334 Forbidden: /accounts/users/me/get-myname/
WARNING 2024-12-29 13:43:39,048 Forbidden: /accounts/users/me/get-myname/
WARNING 2024-12-29 13:43:39,048 Forbidden: /accounts/users/me/get-myname/
WARNING 2024-12-29 13:43:47,568 Forbidden: /accounts/users/me/get-myname/
WARNING 2024-12-29 13:43:47,568 Forbidden: /accounts/users/me/get-myname/
WARNING 2024-12-29 13:43:54,733 Forbidden: /accounts/users/me/get-myname/
WARNING 2024-12-29 13:43:54,733 Forbidden: /accounts/users/me/get-myname/
WARNING 2024-12-29 13:44:04,377 Forbidden: /accounts/users/me/get-myname/
WARNING 2024-12-29 13:44:04,377 Forbidden: /accounts/users/me/get-myname/
WARNING 2024-12-29 14:10:05,348 Forbidden: /accounts/users/me/get-myname/
WARNING 2024-12-29 14:10:05,348 Forbidden: /accounts/users/me/get-myname/
WARNING 2024-12-29 14:47:35,821 Forbidden: /accounts/users/me/get-myname/
WARNING 2024-12-29 14:47:35,821 Forbidden: /accounts/users/me/get-myname/
WARNING 2024-12-29 14:47:53,573 Not Found: /favicon.ico
WARNING 2024-12-29 14:47:53,573 Not Found: /favicon.ico
WARNING 2024-12-29 16:26:54,939 Forbidden: /accounts/users/me/get-myname/
WARNING 2024-12-29 16:26:54,939 Forbidden: /accounts/users/me/get-myname/
WARNING 2024-12-29 16:26:56,376 Forbidden: /accounts/users/me/get-myname/
WARNING 2024-12-29 16:26:56,376 Forbidden: /accounts/users/me/get-myname/
WARNING 2024-12-29 16:26:56,565 Forbidden: /accounts/users/me/get-myname/
WARNING 2024-12-29 16:26:56,565 Forbidden: /accounts/users/me/get-myname/
WARNING 2024-12-29 16:26:56,751 Forbidden: /accounts/users/me/get-myname/
WARNING 2024-12-29 16:26:56,751 Forbidden: /accounts/users/me/get-myname/
WARNING 2024-12-29 16:27:05,535 Forbidden: /accounts/users/me/get-myname/
WARNING 2024-12-29 16:27:05,535 Forbidden: /accounts/users/me/get-myname/
ERROR 2025-01-07 12:52:21,939 Invalid HTTP_HOST header: '10.12.8.3'. You may need to add '10.12.8.3' to ALLOWED_HOSTS.
Traceback (most recent call last):
  File "/usr/local/lib/python3.11/site-packages/asgiref/sync.py", line 518, in thread_handler
    raise exc_info[1]
  File "/usr/local/lib/python3.11/site-packages/django/core/handlers/exception.py", line 42, in inner
    response = await get_response(request)
               ^^^^^^^^^^^^^^^^^^^^^^^^^^^
  File "/usr/local/lib/python3.11/site-packages/django/utils/deprecation.py", line 141, in __acall__
    response = await sync_to_async(
               ^^^^^^^^^^^^^^^^^^^^
  File "/usr/local/lib/python3.11/site-packages/asgiref/sync.py", line 468, in __call__
    ret = await asyncio.shield(exec_coro)
          ^^^^^^^^^^^^^^^^^^^^^^^^^^^^^^^
  File "/usr/local/lib/python3.11/concurrent/futures/thread.py", line 58, in run
    result = self.fn(*self.args, **self.kwargs)
             ^^^^^^^^^^^^^^^^^^^^^^^^^^^^^^^^^^
  File "/usr/local/lib/python3.11/site-packages/asgiref/sync.py", line 522, in thread_handler
    return func(*args, **kwargs)
           ^^^^^^^^^^^^^^^^^^^^^
  File "/usr/local/lib/python3.11/site-packages/django/middleware/common.py", line 48, in process_request
    host = request.get_host()
           ^^^^^^^^^^^^^^^^^^
  File "/usr/local/lib/python3.11/site-packages/django/http/request.py", line 151, in get_host
    raise DisallowedHost(msg)
django.core.exceptions.DisallowedHost: Invalid HTTP_HOST header: '10.12.8.3'. You may need to add '10.12.8.3' to ALLOWED_HOSTS.
ERROR 2025-01-07 12:52:21,939 Invalid HTTP_HOST header: '10.12.8.3'. You may need to add '10.12.8.3' to ALLOWED_HOSTS.
Traceback (most recent call last):
  File "/usr/local/lib/python3.11/site-packages/asgiref/sync.py", line 518, in thread_handler
    raise exc_info[1]
  File "/usr/local/lib/python3.11/site-packages/django/core/handlers/exception.py", line 42, in inner
    response = await get_response(request)
               ^^^^^^^^^^^^^^^^^^^^^^^^^^^
  File "/usr/local/lib/python3.11/site-packages/django/utils/deprecation.py", line 141, in __acall__
    response = await sync_to_async(
               ^^^^^^^^^^^^^^^^^^^^
  File "/usr/local/lib/python3.11/site-packages/asgiref/sync.py", line 468, in __call__
    ret = await asyncio.shield(exec_coro)
          ^^^^^^^^^^^^^^^^^^^^^^^^^^^^^^^
  File "/usr/local/lib/python3.11/concurrent/futures/thread.py", line 58, in run
    result = self.fn(*self.args, **self.kwargs)
             ^^^^^^^^^^^^^^^^^^^^^^^^^^^^^^^^^^
  File "/usr/local/lib/python3.11/site-packages/asgiref/sync.py", line 522, in thread_handler
    return func(*args, **kwargs)
           ^^^^^^^^^^^^^^^^^^^^^
  File "/usr/local/lib/python3.11/site-packages/django/middleware/common.py", line 48, in process_request
    host = request.get_host()
           ^^^^^^^^^^^^^^^^^^
  File "/usr/local/lib/python3.11/site-packages/django/http/request.py", line 151, in get_host
    raise DisallowedHost(msg)
django.core.exceptions.DisallowedHost: Invalid HTTP_HOST header: '10.12.8.3'. You may need to add '10.12.8.3' to ALLOWED_HOSTS.
WARNING 2025-01-07 12:52:22,000 Bad Request: /
WARNING 2025-01-07 12:52:22,000 Bad Request: /
ERROR 2025-01-07 12:52:22,019 Invalid HTTP_HOST header: '10.12.8.3'. You may need to add '10.12.8.3' to ALLOWED_HOSTS.
Traceback (most recent call last):
  File "/usr/local/lib/python3.11/site-packages/asgiref/sync.py", line 518, in thread_handler
    raise exc_info[1]
  File "/usr/local/lib/python3.11/site-packages/django/core/handlers/exception.py", line 42, in inner
    response = await get_response(request)
               ^^^^^^^^^^^^^^^^^^^^^^^^^^^
  File "/usr/local/lib/python3.11/site-packages/django/utils/deprecation.py", line 141, in __acall__
    response = await sync_to_async(
               ^^^^^^^^^^^^^^^^^^^^
  File "/usr/local/lib/python3.11/site-packages/asgiref/sync.py", line 468, in __call__
    ret = await asyncio.shield(exec_coro)
          ^^^^^^^^^^^^^^^^^^^^^^^^^^^^^^^
  File "/usr/local/lib/python3.11/concurrent/futures/thread.py", line 58, in run
    result = self.fn(*self.args, **self.kwargs)
             ^^^^^^^^^^^^^^^^^^^^^^^^^^^^^^^^^^
  File "/usr/local/lib/python3.11/site-packages/asgiref/sync.py", line 522, in thread_handler
    return func(*args, **kwargs)
           ^^^^^^^^^^^^^^^^^^^^^
  File "/usr/local/lib/python3.11/site-packages/django/middleware/common.py", line 48, in process_request
    host = request.get_host()
           ^^^^^^^^^^^^^^^^^^
  File "/usr/local/lib/python3.11/site-packages/django/http/request.py", line 151, in get_host
    raise DisallowedHost(msg)
django.core.exceptions.DisallowedHost: Invalid HTTP_HOST header: '10.12.8.3'. You may need to add '10.12.8.3' to ALLOWED_HOSTS.
ERROR 2025-01-07 12:52:22,019 Invalid HTTP_HOST header: '10.12.8.3'. You may need to add '10.12.8.3' to ALLOWED_HOSTS.
Traceback (most recent call last):
  File "/usr/local/lib/python3.11/site-packages/asgiref/sync.py", line 518, in thread_handler
    raise exc_info[1]
  File "/usr/local/lib/python3.11/site-packages/django/core/handlers/exception.py", line 42, in inner
    response = await get_response(request)
               ^^^^^^^^^^^^^^^^^^^^^^^^^^^
  File "/usr/local/lib/python3.11/site-packages/django/utils/deprecation.py", line 141, in __acall__
    response = await sync_to_async(
               ^^^^^^^^^^^^^^^^^^^^
  File "/usr/local/lib/python3.11/site-packages/asgiref/sync.py", line 468, in __call__
    ret = await asyncio.shield(exec_coro)
          ^^^^^^^^^^^^^^^^^^^^^^^^^^^^^^^
  File "/usr/local/lib/python3.11/concurrent/futures/thread.py", line 58, in run
    result = self.fn(*self.args, **self.kwargs)
             ^^^^^^^^^^^^^^^^^^^^^^^^^^^^^^^^^^
  File "/usr/local/lib/python3.11/site-packages/asgiref/sync.py", line 522, in thread_handler
    return func(*args, **kwargs)
           ^^^^^^^^^^^^^^^^^^^^^
  File "/usr/local/lib/python3.11/site-packages/django/middleware/common.py", line 48, in process_request
    host = request.get_host()
           ^^^^^^^^^^^^^^^^^^
  File "/usr/local/lib/python3.11/site-packages/django/http/request.py", line 151, in get_host
    raise DisallowedHost(msg)
django.core.exceptions.DisallowedHost: Invalid HTTP_HOST header: '10.12.8.3'. You may need to add '10.12.8.3' to ALLOWED_HOSTS.
WARNING 2025-01-07 12:52:22,026 Bad Request: /favicon.ico
WARNING 2025-01-07 12:52:22,026 Bad Request: /favicon.ico
WARNING 2025-01-07 12:52:54,729 Forbidden: /accounts/users/me/get-myname/
WARNING 2025-01-07 12:52:54,729 Forbidden: /accounts/users/me/get-myname/
WARNING 2025-01-07 13:42:02,438 Forbidden: /accounts/users/me/get-myname/
WARNING 2025-01-07 13:42:02,438 Forbidden: /accounts/users/me/get-myname/
WARNING 2025-01-07 16:08:18,312 Room hello is full. Connection rejected.
ERROR 2025-01-07 16:08:44,978 Error in game loop: cannot access local variable 'frame_per_second' where it is not associated with a value
ERROR 2025-01-07 16:08:44,979 Error in game loop: cannot access local variable 'frame_per_second' where it is not associated with a value
WARNING 2025-01-07 16:08:53,857 Room hello is full. Connection rejected.
ERROR 2025-01-07 16:45:02,563 Error in game loop: cannot access local variable 'frame_per_second' where it is not associated with a value
ERROR 2025-01-07 17:06:47,627 Disconnect error: Error while reading from redis:6379 : (104, 'Connection reset by peer')
WARNING 2025-01-08 12:35:50,936 Not Found: /api/users/online-users/
WARNING 2025-01-08 12:35:50,936 Not Found: /api/users/online-users/
WARNING 2025-01-08 12:36:06,602 Not Found: /api/users/online-users/
WARNING 2025-01-08 12:36:06,602 Not Found: /api/users/online-users/
WARNING 2025-01-08 12:36:37,193 Not Found: /static/home/style.css
WARNING 2025-01-08 12:36:37,193 Not Found: /static/home/style.css
WARNING 2025-01-08 12:36:37,194 Not Found: /static/home/js/home.js
WARNING 2025-01-08 12:36:37,194 Not Found: /static/home/js/home.js
WARNING 2025-01-08 12:36:37,194 Not Found: /static/chat/js/chat.js
WARNING 2025-01-08 12:36:37,194 Not Found: /static/chat/js/chat.js
WARNING 2025-01-08 12:36:37,199 Not Found: /static/home/js/home.js
WARNING 2025-01-08 12:36:37,199 Not Found: /static/home/js/home.js
WARNING 2025-01-08 12:36:37,411 Not Found: /favicon.ico
WARNING 2025-01-08 12:36:37,411 Not Found: /favicon.ico
WARNING 2025-01-08 12:36:51,535 Not Found: /api/users/online-users
WARNING 2025-01-08 12:36:51,535 Not Found: /api/users/online-users
WARNING 2025-01-08 12:38:01,833 Forbidden: /api/user/online-users/
WARNING 2025-01-08 12:38:01,833 Forbidden: /api/user/online-users/
WARNING 2025-01-08 12:38:01,906 Not Found: /static/rest_framework/css/bootstrap-tweaks.css
WARNING 2025-01-08 12:38:01,906 Not Found: /static/rest_framework/css/bootstrap-tweaks.css
WARNING 2025-01-08 12:38:01,907 Not Found: /static/rest_framework/css/bootstrap.min.css
WARNING 2025-01-08 12:38:01,907 Not Found: /static/rest_framework/css/bootstrap.min.css
WARNING 2025-01-08 12:38:01,908 Not Found: /static/rest_framework/css/default.css
WARNING 2025-01-08 12:38:01,908 Not Found: /static/rest_framework/css/default.css
WARNING 2025-01-08 12:38:01,910 Not Found: /static/rest_framework/css/prettify.css
WARNING 2025-01-08 12:38:01,910 Not Found: /static/rest_framework/css/prettify.css
WARNING 2025-01-08 12:38:01,916 Not Found: /static/rest_framework/js/jquery-3.7.1.min.js
WARNING 2025-01-08 12:38:01,916 Not Found: /static/rest_framework/js/jquery-3.7.1.min.js
WARNING 2025-01-08 12:38:01,916 Not Found: /static/rest_framework/js/ajax-form.js
WARNING 2025-01-08 12:38:01,916 Not Found: /static/rest_framework/js/ajax-form.js
WARNING 2025-01-08 12:38:01,936 Not Found: /static/rest_framework/js/csrf.js
WARNING 2025-01-08 12:38:01,936 Not Found: /static/rest_framework/js/csrf.js
WARNING 2025-01-08 12:38:01,936 Not Found: /static/rest_framework/js/default.js
WARNING 2025-01-08 12:38:01,936 Not Found: /static/rest_framework/js/default.js
WARNING 2025-01-08 12:38:01,937 Not Found: /static/rest_framework/js/bootstrap.min.js
WARNING 2025-01-08 12:38:01,937 Not Found: /static/rest_framework/js/bootstrap.min.js
WARNING 2025-01-08 12:38:01,937 Not Found: /static/rest_framework/js/load-ajax-form.js
WARNING 2025-01-08 12:38:01,937 Not Found: /static/rest_framework/js/load-ajax-form.js
WARNING 2025-01-08 12:38:01,938 Not Found: /static/rest_framework/js/prettify-min.js
WARNING 2025-01-08 12:38:01,938 Not Found: /static/rest_framework/js/prettify-min.js
WARNING 2025-01-08 12:38:01,942 Not Found: /static/rest_framework/js/default.js
WARNING 2025-01-08 12:38:01,942 Not Found: /static/rest_framework/js/default.js
WARNING 2025-01-08 12:38:01,945 Not Found: /static/rest_framework/js/load-ajax-form.js
WARNING 2025-01-08 12:38:01,945 Not Found: /static/rest_framework/js/load-ajax-form.js
WARNING 2025-01-08 12:39:17,551 Forbidden: /api/user/online-users/
WARNING 2025-01-08 12:39:17,551 Forbidden: /api/user/online-users/
WARNING 2025-01-08 13:25:46,850 Forbidden: /api/user/online-users/
WARNING 2025-01-08 13:25:46,850 Forbidden: /api/user/online-users/
WARNING 2025-01-08 13:46:03,833 Forbidden: /api/oauth/callback/
WARNING 2025-01-08 13:46:03,833 Forbidden: /api/oauth/callback/
WARNING 2025-01-08 13:46:29,818 Forbidden: /api/oauth/callback/
WARNING 2025-01-08 13:46:29,818 Forbidden: /api/oauth/callback/
ERROR 2025-01-08 13:51:04,518 Internal Server Error: /api/oauth/callback/
Traceback (most recent call last):
  File "/usr/local/lib/python3.11/site-packages/django/db/backends/utils.py", line 105, in _execute
    return self.cursor.execute(sql, params)
           ^^^^^^^^^^^^^^^^^^^^^^^^^^^^^^^^
psycopg2.errors.UndefinedTable: relation "auth_user" does not exist
LINE 1: ...user"."is_active", "auth_user"."date_joined" FROM "auth_user...
                                                             ^


The above exception was the direct cause of the following exception:

Traceback (most recent call last):
  File "/usr/local/lib/python3.11/site-packages/asgiref/sync.py", line 518, in thread_handler
    raise exc_info[1]
  File "/usr/local/lib/python3.11/site-packages/django/core/handlers/exception.py", line 42, in inner
    response = await get_response(request)
               ^^^^^^^^^^^^^^^^^^^^^^^^^^^
  File "/usr/local/lib/python3.11/site-packages/asgiref/sync.py", line 518, in thread_handler
    raise exc_info[1]
  File "/usr/local/lib/python3.11/site-packages/django/core/handlers/base.py", line 253, in _get_response_async
    response = await wrapped_callback(
               ^^^^^^^^^^^^^^^^^^^^^^^
  File "/usr/local/lib/python3.11/site-packages/asgiref/sync.py", line 468, in __call__
    ret = await asyncio.shield(exec_coro)
          ^^^^^^^^^^^^^^^^^^^^^^^^^^^^^^^
  File "/usr/local/lib/python3.11/concurrent/futures/thread.py", line 58, in run
    result = self.fn(*self.args, **self.kwargs)
             ^^^^^^^^^^^^^^^^^^^^^^^^^^^^^^^^^^
  File "/usr/local/lib/python3.11/site-packages/asgiref/sync.py", line 522, in thread_handler
    return func(*args, **kwargs)
           ^^^^^^^^^^^^^^^^^^^^^
  File "/usr/local/lib/python3.11/site-packages/django/views/decorators/csrf.py", line 65, in _view_wrapper
    return view_func(request, *args, **kwargs)
           ^^^^^^^^^^^^^^^^^^^^^^^^^^^^^^^^^^^
  File "/usr/local/lib/python3.11/site-packages/rest_framework/viewsets.py", line 124, in view
    return self.dispatch(request, *args, **kwargs)
           ^^^^^^^^^^^^^^^^^^^^^^^^^^^^^^^^^^^^^^^
  File "/usr/local/lib/python3.11/site-packages/rest_framework/views.py", line 509, in dispatch
    response = self.handle_exception(exc)
               ^^^^^^^^^^^^^^^^^^^^^^^^^^
  File "/usr/local/lib/python3.11/site-packages/rest_framework/views.py", line 469, in handle_exception
    self.raise_uncaught_exception(exc)
  File "/usr/local/lib/python3.11/site-packages/rest_framework/views.py", line 480, in raise_uncaught_exception
    raise exc
  File "/usr/local/lib/python3.11/site-packages/rest_framework/views.py", line 506, in dispatch
    response = handler(request, *args, **kwargs)
               ^^^^^^^^^^^^^^^^^^^^^^^^^^^^^^^^^
  File "/home/accounts/views.py", line 55, in oauth_callback
    user = create_or_update_user(user_info)
           ^^^^^^^^^^^^^^^^^^^^^^^^^^^^^^^^
  File "/home/accounts/services.py", line 43, in create_or_update_user
    user, created = User.objects.get_or_create(
                    ^^^^^^^^^^^^^^^^^^^^^^^^^^^
  File "/usr/local/lib/python3.11/site-packages/django/db/models/manager.py", line 87, in manager_method
    return getattr(self.get_queryset(), name)(*args, **kwargs)
           ^^^^^^^^^^^^^^^^^^^^^^^^^^^^^^^^^^^^^^^^^^^^^^^^^^^
  File "/usr/local/lib/python3.11/site-packages/django/db/models/query.py", line 948, in get_or_create
    return self.get(**kwargs), False
           ^^^^^^^^^^^^^^^^^^
  File "/usr/local/lib/python3.11/site-packages/django/db/models/query.py", line 645, in get
    num = len(clone)
          ^^^^^^^^^^
  File "/usr/local/lib/python3.11/site-packages/django/db/models/query.py", line 382, in __len__
    self._fetch_all()
  File "/usr/local/lib/python3.11/site-packages/django/db/models/query.py", line 1928, in _fetch_all
    self._result_cache = list(self._iterable_class(self))
                         ^^^^^^^^^^^^^^^^^^^^^^^^^^^^^^^^
  File "/usr/local/lib/python3.11/site-packages/django/db/models/query.py", line 91, in __iter__
    results = compiler.execute_sql(
              ^^^^^^^^^^^^^^^^^^^^^
  File "/usr/local/lib/python3.11/site-packages/django/db/models/sql/compiler.py", line 1574, in execute_sql
    cursor.execute(sql, params)
  File "/usr/local/lib/python3.11/site-packages/django/db/backends/utils.py", line 122, in execute
    return super().execute(sql, params)
           ^^^^^^^^^^^^^^^^^^^^^^^^^^^^
  File "/usr/local/lib/python3.11/site-packages/django/db/backends/utils.py", line 79, in execute
    return self._execute_with_wrappers(
           ^^^^^^^^^^^^^^^^^^^^^^^^^^^^
  File "/usr/local/lib/python3.11/site-packages/django/db/backends/utils.py", line 92, in _execute_with_wrappers
    return executor(sql, params, many, context)
           ^^^^^^^^^^^^^^^^^^^^^^^^^^^^^^^^^^^^
  File "/usr/local/lib/python3.11/site-packages/django/db/backends/utils.py", line 100, in _execute
    with self.db.wrap_database_errors:
  File "/usr/local/lib/python3.11/site-packages/django/db/utils.py", line 91, in __exit__
    raise dj_exc_value.with_traceback(traceback) from exc_value
  File "/usr/local/lib/python3.11/site-packages/django/db/backends/utils.py", line 105, in _execute
    return self.cursor.execute(sql, params)
           ^^^^^^^^^^^^^^^^^^^^^^^^^^^^^^^^
django.db.utils.ProgrammingError: relation "auth_user" does not exist
LINE 1: ...user"."is_active", "auth_user"."date_joined" FROM "auth_user...
                                                             ^

ERROR 2025-01-08 13:51:04,518 Internal Server Error: /api/oauth/callback/
Traceback (most recent call last):
  File "/usr/local/lib/python3.11/site-packages/django/db/backends/utils.py", line 105, in _execute
    return self.cursor.execute(sql, params)
           ^^^^^^^^^^^^^^^^^^^^^^^^^^^^^^^^
psycopg2.errors.UndefinedTable: relation "auth_user" does not exist
LINE 1: ...user"."is_active", "auth_user"."date_joined" FROM "auth_user...
                                                             ^


The above exception was the direct cause of the following exception:

Traceback (most recent call last):
  File "/usr/local/lib/python3.11/site-packages/asgiref/sync.py", line 518, in thread_handler
    raise exc_info[1]
  File "/usr/local/lib/python3.11/site-packages/django/core/handlers/exception.py", line 42, in inner
    response = await get_response(request)
               ^^^^^^^^^^^^^^^^^^^^^^^^^^^
  File "/usr/local/lib/python3.11/site-packages/asgiref/sync.py", line 518, in thread_handler
    raise exc_info[1]
  File "/usr/local/lib/python3.11/site-packages/django/core/handlers/base.py", line 253, in _get_response_async
    response = await wrapped_callback(
               ^^^^^^^^^^^^^^^^^^^^^^^
  File "/usr/local/lib/python3.11/site-packages/asgiref/sync.py", line 468, in __call__
    ret = await asyncio.shield(exec_coro)
          ^^^^^^^^^^^^^^^^^^^^^^^^^^^^^^^
  File "/usr/local/lib/python3.11/concurrent/futures/thread.py", line 58, in run
    result = self.fn(*self.args, **self.kwargs)
             ^^^^^^^^^^^^^^^^^^^^^^^^^^^^^^^^^^
  File "/usr/local/lib/python3.11/site-packages/asgiref/sync.py", line 522, in thread_handler
    return func(*args, **kwargs)
           ^^^^^^^^^^^^^^^^^^^^^
  File "/usr/local/lib/python3.11/site-packages/django/views/decorators/csrf.py", line 65, in _view_wrapper
    return view_func(request, *args, **kwargs)
           ^^^^^^^^^^^^^^^^^^^^^^^^^^^^^^^^^^^
  File "/usr/local/lib/python3.11/site-packages/rest_framework/viewsets.py", line 124, in view
    return self.dispatch(request, *args, **kwargs)
           ^^^^^^^^^^^^^^^^^^^^^^^^^^^^^^^^^^^^^^^
  File "/usr/local/lib/python3.11/site-packages/rest_framework/views.py", line 509, in dispatch
    response = self.handle_exception(exc)
               ^^^^^^^^^^^^^^^^^^^^^^^^^^
  File "/usr/local/lib/python3.11/site-packages/rest_framework/views.py", line 469, in handle_exception
    self.raise_uncaught_exception(exc)
  File "/usr/local/lib/python3.11/site-packages/rest_framework/views.py", line 480, in raise_uncaught_exception
    raise exc
  File "/usr/local/lib/python3.11/site-packages/rest_framework/views.py", line 506, in dispatch
    response = handler(request, *args, **kwargs)
               ^^^^^^^^^^^^^^^^^^^^^^^^^^^^^^^^^
  File "/home/accounts/views.py", line 55, in oauth_callback
    user = create_or_update_user(user_info)
           ^^^^^^^^^^^^^^^^^^^^^^^^^^^^^^^^
  File "/home/accounts/services.py", line 43, in create_or_update_user
    user, created = User.objects.get_or_create(
                    ^^^^^^^^^^^^^^^^^^^^^^^^^^^
  File "/usr/local/lib/python3.11/site-packages/django/db/models/manager.py", line 87, in manager_method
    return getattr(self.get_queryset(), name)(*args, **kwargs)
           ^^^^^^^^^^^^^^^^^^^^^^^^^^^^^^^^^^^^^^^^^^^^^^^^^^^
  File "/usr/local/lib/python3.11/site-packages/django/db/models/query.py", line 948, in get_or_create
    return self.get(**kwargs), False
           ^^^^^^^^^^^^^^^^^^
  File "/usr/local/lib/python3.11/site-packages/django/db/models/query.py", line 645, in get
    num = len(clone)
          ^^^^^^^^^^
  File "/usr/local/lib/python3.11/site-packages/django/db/models/query.py", line 382, in __len__
    self._fetch_all()
  File "/usr/local/lib/python3.11/site-packages/django/db/models/query.py", line 1928, in _fetch_all
    self._result_cache = list(self._iterable_class(self))
                         ^^^^^^^^^^^^^^^^^^^^^^^^^^^^^^^^
  File "/usr/local/lib/python3.11/site-packages/django/db/models/query.py", line 91, in __iter__
    results = compiler.execute_sql(
              ^^^^^^^^^^^^^^^^^^^^^
  File "/usr/local/lib/python3.11/site-packages/django/db/models/sql/compiler.py", line 1574, in execute_sql
    cursor.execute(sql, params)
  File "/usr/local/lib/python3.11/site-packages/django/db/backends/utils.py", line 122, in execute
    return super().execute(sql, params)
           ^^^^^^^^^^^^^^^^^^^^^^^^^^^^
  File "/usr/local/lib/python3.11/site-packages/django/db/backends/utils.py", line 79, in execute
    return self._execute_with_wrappers(
           ^^^^^^^^^^^^^^^^^^^^^^^^^^^^
  File "/usr/local/lib/python3.11/site-packages/django/db/backends/utils.py", line 92, in _execute_with_wrappers
    return executor(sql, params, many, context)
           ^^^^^^^^^^^^^^^^^^^^^^^^^^^^^^^^^^^^
  File "/usr/local/lib/python3.11/site-packages/django/db/backends/utils.py", line 100, in _execute
    with self.db.wrap_database_errors:
  File "/usr/local/lib/python3.11/site-packages/django/db/utils.py", line 91, in __exit__
    raise dj_exc_value.with_traceback(traceback) from exc_value
  File "/usr/local/lib/python3.11/site-packages/django/db/backends/utils.py", line 105, in _execute
    return self.cursor.execute(sql, params)
           ^^^^^^^^^^^^^^^^^^^^^^^^^^^^^^^^
django.db.utils.ProgrammingError: relation "auth_user" does not exist
LINE 1: ...user"."is_active", "auth_user"."date_joined" FROM "auth_user...
                                                             ^

ERROR 2025-01-08 13:51:45,590 Internal Server Error: /api/oauth/callback/
Traceback (most recent call last):
  File "/usr/local/lib/python3.11/site-packages/django/db/backends/utils.py", line 105, in _execute
    return self.cursor.execute(sql, params)
           ^^^^^^^^^^^^^^^^^^^^^^^^^^^^^^^^
psycopg2.errors.UndefinedTable: relation "auth_user" does not exist
LINE 1: ...user"."is_active", "auth_user"."date_joined" FROM "auth_user...
                                                             ^


The above exception was the direct cause of the following exception:

Traceback (most recent call last):
  File "/usr/local/lib/python3.11/site-packages/asgiref/sync.py", line 518, in thread_handler
    raise exc_info[1]
  File "/usr/local/lib/python3.11/site-packages/django/core/handlers/exception.py", line 42, in inner
    response = await get_response(request)
               ^^^^^^^^^^^^^^^^^^^^^^^^^^^
  File "/usr/local/lib/python3.11/site-packages/asgiref/sync.py", line 518, in thread_handler
    raise exc_info[1]
  File "/usr/local/lib/python3.11/site-packages/django/core/handlers/base.py", line 253, in _get_response_async
    response = await wrapped_callback(
               ^^^^^^^^^^^^^^^^^^^^^^^
  File "/usr/local/lib/python3.11/site-packages/asgiref/sync.py", line 468, in __call__
    ret = await asyncio.shield(exec_coro)
          ^^^^^^^^^^^^^^^^^^^^^^^^^^^^^^^
  File "/usr/local/lib/python3.11/concurrent/futures/thread.py", line 58, in run
    result = self.fn(*self.args, **self.kwargs)
             ^^^^^^^^^^^^^^^^^^^^^^^^^^^^^^^^^^
  File "/usr/local/lib/python3.11/site-packages/asgiref/sync.py", line 522, in thread_handler
    return func(*args, **kwargs)
           ^^^^^^^^^^^^^^^^^^^^^
  File "/usr/local/lib/python3.11/site-packages/django/views/decorators/csrf.py", line 65, in _view_wrapper
    return view_func(request, *args, **kwargs)
           ^^^^^^^^^^^^^^^^^^^^^^^^^^^^^^^^^^^
  File "/usr/local/lib/python3.11/site-packages/rest_framework/viewsets.py", line 124, in view
    return self.dispatch(request, *args, **kwargs)
           ^^^^^^^^^^^^^^^^^^^^^^^^^^^^^^^^^^^^^^^
  File "/usr/local/lib/python3.11/site-packages/rest_framework/views.py", line 509, in dispatch
    response = self.handle_exception(exc)
               ^^^^^^^^^^^^^^^^^^^^^^^^^^
  File "/usr/local/lib/python3.11/site-packages/rest_framework/views.py", line 469, in handle_exception
    self.raise_uncaught_exception(exc)
  File "/usr/local/lib/python3.11/site-packages/rest_framework/views.py", line 480, in raise_uncaught_exception
    raise exc
  File "/usr/local/lib/python3.11/site-packages/rest_framework/views.py", line 506, in dispatch
    response = handler(request, *args, **kwargs)
               ^^^^^^^^^^^^^^^^^^^^^^^^^^^^^^^^^
  File "/home/accounts/views.py", line 55, in oauth_callback
    user = create_or_update_user(user_info)
           ^^^^^^^^^^^^^^^^^^^^^^^^^^^^^^^^
  File "/home/accounts/services.py", line 43, in create_or_update_user
    user, created = User.objects.get_or_create(
                    ^^^^^^^^^^^^^^^^^^^^^^^^^^^
  File "/usr/local/lib/python3.11/site-packages/django/db/models/manager.py", line 87, in manager_method
    return getattr(self.get_queryset(), name)(*args, **kwargs)
           ^^^^^^^^^^^^^^^^^^^^^^^^^^^^^^^^^^^^^^^^^^^^^^^^^^^
  File "/usr/local/lib/python3.11/site-packages/django/db/models/query.py", line 948, in get_or_create
    return self.get(**kwargs), False
           ^^^^^^^^^^^^^^^^^^
  File "/usr/local/lib/python3.11/site-packages/django/db/models/query.py", line 645, in get
    num = len(clone)
          ^^^^^^^^^^
  File "/usr/local/lib/python3.11/site-packages/django/db/models/query.py", line 382, in __len__
    self._fetch_all()
  File "/usr/local/lib/python3.11/site-packages/django/db/models/query.py", line 1928, in _fetch_all
    self._result_cache = list(self._iterable_class(self))
                         ^^^^^^^^^^^^^^^^^^^^^^^^^^^^^^^^
  File "/usr/local/lib/python3.11/site-packages/django/db/models/query.py", line 91, in __iter__
    results = compiler.execute_sql(
              ^^^^^^^^^^^^^^^^^^^^^
  File "/usr/local/lib/python3.11/site-packages/django/db/models/sql/compiler.py", line 1574, in execute_sql
    cursor.execute(sql, params)
  File "/usr/local/lib/python3.11/site-packages/django/db/backends/utils.py", line 122, in execute
    return super().execute(sql, params)
           ^^^^^^^^^^^^^^^^^^^^^^^^^^^^
  File "/usr/local/lib/python3.11/site-packages/django/db/backends/utils.py", line 79, in execute
    return self._execute_with_wrappers(
           ^^^^^^^^^^^^^^^^^^^^^^^^^^^^
  File "/usr/local/lib/python3.11/site-packages/django/db/backends/utils.py", line 92, in _execute_with_wrappers
    return executor(sql, params, many, context)
           ^^^^^^^^^^^^^^^^^^^^^^^^^^^^^^^^^^^^
  File "/usr/local/lib/python3.11/site-packages/django/db/backends/utils.py", line 100, in _execute
    with self.db.wrap_database_errors:
  File "/usr/local/lib/python3.11/site-packages/django/db/utils.py", line 91, in __exit__
    raise dj_exc_value.with_traceback(traceback) from exc_value
  File "/usr/local/lib/python3.11/site-packages/django/db/backends/utils.py", line 105, in _execute
    return self.cursor.execute(sql, params)
           ^^^^^^^^^^^^^^^^^^^^^^^^^^^^^^^^
django.db.utils.ProgrammingError: relation "auth_user" does not exist
LINE 1: ...user"."is_active", "auth_user"."date_joined" FROM "auth_user...
                                                             ^

ERROR 2025-01-08 13:51:45,590 Internal Server Error: /api/oauth/callback/
Traceback (most recent call last):
  File "/usr/local/lib/python3.11/site-packages/django/db/backends/utils.py", line 105, in _execute
    return self.cursor.execute(sql, params)
           ^^^^^^^^^^^^^^^^^^^^^^^^^^^^^^^^
psycopg2.errors.UndefinedTable: relation "auth_user" does not exist
LINE 1: ...user"."is_active", "auth_user"."date_joined" FROM "auth_user...
                                                             ^


The above exception was the direct cause of the following exception:

Traceback (most recent call last):
  File "/usr/local/lib/python3.11/site-packages/asgiref/sync.py", line 518, in thread_handler
    raise exc_info[1]
  File "/usr/local/lib/python3.11/site-packages/django/core/handlers/exception.py", line 42, in inner
    response = await get_response(request)
               ^^^^^^^^^^^^^^^^^^^^^^^^^^^
  File "/usr/local/lib/python3.11/site-packages/asgiref/sync.py", line 518, in thread_handler
    raise exc_info[1]
  File "/usr/local/lib/python3.11/site-packages/django/core/handlers/base.py", line 253, in _get_response_async
    response = await wrapped_callback(
               ^^^^^^^^^^^^^^^^^^^^^^^
  File "/usr/local/lib/python3.11/site-packages/asgiref/sync.py", line 468, in __call__
    ret = await asyncio.shield(exec_coro)
          ^^^^^^^^^^^^^^^^^^^^^^^^^^^^^^^
  File "/usr/local/lib/python3.11/concurrent/futures/thread.py", line 58, in run
    result = self.fn(*self.args, **self.kwargs)
             ^^^^^^^^^^^^^^^^^^^^^^^^^^^^^^^^^^
  File "/usr/local/lib/python3.11/site-packages/asgiref/sync.py", line 522, in thread_handler
    return func(*args, **kwargs)
           ^^^^^^^^^^^^^^^^^^^^^
  File "/usr/local/lib/python3.11/site-packages/django/views/decorators/csrf.py", line 65, in _view_wrapper
    return view_func(request, *args, **kwargs)
           ^^^^^^^^^^^^^^^^^^^^^^^^^^^^^^^^^^^
  File "/usr/local/lib/python3.11/site-packages/rest_framework/viewsets.py", line 124, in view
    return self.dispatch(request, *args, **kwargs)
           ^^^^^^^^^^^^^^^^^^^^^^^^^^^^^^^^^^^^^^^
  File "/usr/local/lib/python3.11/site-packages/rest_framework/views.py", line 509, in dispatch
    response = self.handle_exception(exc)
               ^^^^^^^^^^^^^^^^^^^^^^^^^^
  File "/usr/local/lib/python3.11/site-packages/rest_framework/views.py", line 469, in handle_exception
    self.raise_uncaught_exception(exc)
  File "/usr/local/lib/python3.11/site-packages/rest_framework/views.py", line 480, in raise_uncaught_exception
    raise exc
  File "/usr/local/lib/python3.11/site-packages/rest_framework/views.py", line 506, in dispatch
    response = handler(request, *args, **kwargs)
               ^^^^^^^^^^^^^^^^^^^^^^^^^^^^^^^^^
  File "/home/accounts/views.py", line 55, in oauth_callback
    user = create_or_update_user(user_info)
           ^^^^^^^^^^^^^^^^^^^^^^^^^^^^^^^^
  File "/home/accounts/services.py", line 43, in create_or_update_user
    user, created = User.objects.get_or_create(
                    ^^^^^^^^^^^^^^^^^^^^^^^^^^^
  File "/usr/local/lib/python3.11/site-packages/django/db/models/manager.py", line 87, in manager_method
    return getattr(self.get_queryset(), name)(*args, **kwargs)
           ^^^^^^^^^^^^^^^^^^^^^^^^^^^^^^^^^^^^^^^^^^^^^^^^^^^
  File "/usr/local/lib/python3.11/site-packages/django/db/models/query.py", line 948, in get_or_create
    return self.get(**kwargs), False
           ^^^^^^^^^^^^^^^^^^
  File "/usr/local/lib/python3.11/site-packages/django/db/models/query.py", line 645, in get
    num = len(clone)
          ^^^^^^^^^^
  File "/usr/local/lib/python3.11/site-packages/django/db/models/query.py", line 382, in __len__
    self._fetch_all()
  File "/usr/local/lib/python3.11/site-packages/django/db/models/query.py", line 1928, in _fetch_all
    self._result_cache = list(self._iterable_class(self))
                         ^^^^^^^^^^^^^^^^^^^^^^^^^^^^^^^^
  File "/usr/local/lib/python3.11/site-packages/django/db/models/query.py", line 91, in __iter__
    results = compiler.execute_sql(
              ^^^^^^^^^^^^^^^^^^^^^
  File "/usr/local/lib/python3.11/site-packages/django/db/models/sql/compiler.py", line 1574, in execute_sql
    cursor.execute(sql, params)
  File "/usr/local/lib/python3.11/site-packages/django/db/backends/utils.py", line 122, in execute
    return super().execute(sql, params)
           ^^^^^^^^^^^^^^^^^^^^^^^^^^^^
  File "/usr/local/lib/python3.11/site-packages/django/db/backends/utils.py", line 79, in execute
    return self._execute_with_wrappers(
           ^^^^^^^^^^^^^^^^^^^^^^^^^^^^
  File "/usr/local/lib/python3.11/site-packages/django/db/backends/utils.py", line 92, in _execute_with_wrappers
    return executor(sql, params, many, context)
           ^^^^^^^^^^^^^^^^^^^^^^^^^^^^^^^^^^^^
  File "/usr/local/lib/python3.11/site-packages/django/db/backends/utils.py", line 100, in _execute
    with self.db.wrap_database_errors:
  File "/usr/local/lib/python3.11/site-packages/django/db/utils.py", line 91, in __exit__
    raise dj_exc_value.with_traceback(traceback) from exc_value
  File "/usr/local/lib/python3.11/site-packages/django/db/backends/utils.py", line 105, in _execute
    return self.cursor.execute(sql, params)
           ^^^^^^^^^^^^^^^^^^^^^^^^^^^^^^^^
django.db.utils.ProgrammingError: relation "auth_user" does not exist
LINE 1: ...user"."is_active", "auth_user"."date_joined" FROM "auth_user...
                                                             ^

ERROR 2025-01-08 13:54:22,338 Internal Server Error: /api/oauth/callback/
Traceback (most recent call last):
  File "/usr/local/lib/python3.11/site-packages/asgiref/sync.py", line 518, in thread_handler
    raise exc_info[1]
  File "/usr/local/lib/python3.11/site-packages/django/core/handlers/exception.py", line 42, in inner
    response = await get_response(request)
               ^^^^^^^^^^^^^^^^^^^^^^^^^^^
  File "/usr/local/lib/python3.11/site-packages/asgiref/sync.py", line 518, in thread_handler
    raise exc_info[1]
  File "/usr/local/lib/python3.11/site-packages/django/core/handlers/base.py", line 253, in _get_response_async
    response = await wrapped_callback(
               ^^^^^^^^^^^^^^^^^^^^^^^
  File "/usr/local/lib/python3.11/site-packages/asgiref/sync.py", line 468, in __call__
    ret = await asyncio.shield(exec_coro)
          ^^^^^^^^^^^^^^^^^^^^^^^^^^^^^^^
  File "/usr/local/lib/python3.11/concurrent/futures/thread.py", line 58, in run
    result = self.fn(*self.args, **self.kwargs)
             ^^^^^^^^^^^^^^^^^^^^^^^^^^^^^^^^^^
  File "/usr/local/lib/python3.11/site-packages/asgiref/sync.py", line 522, in thread_handler
    return func(*args, **kwargs)
           ^^^^^^^^^^^^^^^^^^^^^
  File "/usr/local/lib/python3.11/site-packages/django/views/decorators/csrf.py", line 65, in _view_wrapper
    return view_func(request, *args, **kwargs)
           ^^^^^^^^^^^^^^^^^^^^^^^^^^^^^^^^^^^
  File "/usr/local/lib/python3.11/site-packages/rest_framework/viewsets.py", line 124, in view
    return self.dispatch(request, *args, **kwargs)
           ^^^^^^^^^^^^^^^^^^^^^^^^^^^^^^^^^^^^^^^
  File "/usr/local/lib/python3.11/site-packages/rest_framework/views.py", line 509, in dispatch
    response = self.handle_exception(exc)
               ^^^^^^^^^^^^^^^^^^^^^^^^^^
  File "/usr/local/lib/python3.11/site-packages/rest_framework/views.py", line 469, in handle_exception
    self.raise_uncaught_exception(exc)
  File "/usr/local/lib/python3.11/site-packages/rest_framework/views.py", line 480, in raise_uncaught_exception
    raise exc
  File "/usr/local/lib/python3.11/site-packages/rest_framework/views.py", line 506, in dispatch
    response = handler(request, *args, **kwargs)
               ^^^^^^^^^^^^^^^^^^^^^^^^^^^^^^^^^
  File "/home/accounts/views.py", line 57, in oauth_callback
    return redirect('home:home')
           ^^^^^^^^
NameError: name 'redirect' is not defined
ERROR 2025-01-08 13:54:22,338 Internal Server Error: /api/oauth/callback/
Traceback (most recent call last):
  File "/usr/local/lib/python3.11/site-packages/asgiref/sync.py", line 518, in thread_handler
    raise exc_info[1]
  File "/usr/local/lib/python3.11/site-packages/django/core/handlers/exception.py", line 42, in inner
    response = await get_response(request)
               ^^^^^^^^^^^^^^^^^^^^^^^^^^^
  File "/usr/local/lib/python3.11/site-packages/asgiref/sync.py", line 518, in thread_handler
    raise exc_info[1]
  File "/usr/local/lib/python3.11/site-packages/django/core/handlers/base.py", line 253, in _get_response_async
    response = await wrapped_callback(
               ^^^^^^^^^^^^^^^^^^^^^^^
  File "/usr/local/lib/python3.11/site-packages/asgiref/sync.py", line 468, in __call__
    ret = await asyncio.shield(exec_coro)
          ^^^^^^^^^^^^^^^^^^^^^^^^^^^^^^^
  File "/usr/local/lib/python3.11/concurrent/futures/thread.py", line 58, in run
    result = self.fn(*self.args, **self.kwargs)
             ^^^^^^^^^^^^^^^^^^^^^^^^^^^^^^^^^^
  File "/usr/local/lib/python3.11/site-packages/asgiref/sync.py", line 522, in thread_handler
    return func(*args, **kwargs)
           ^^^^^^^^^^^^^^^^^^^^^
  File "/usr/local/lib/python3.11/site-packages/django/views/decorators/csrf.py", line 65, in _view_wrapper
    return view_func(request, *args, **kwargs)
           ^^^^^^^^^^^^^^^^^^^^^^^^^^^^^^^^^^^
  File "/usr/local/lib/python3.11/site-packages/rest_framework/viewsets.py", line 124, in view
    return self.dispatch(request, *args, **kwargs)
           ^^^^^^^^^^^^^^^^^^^^^^^^^^^^^^^^^^^^^^^
  File "/usr/local/lib/python3.11/site-packages/rest_framework/views.py", line 509, in dispatch
    response = self.handle_exception(exc)
               ^^^^^^^^^^^^^^^^^^^^^^^^^^
  File "/usr/local/lib/python3.11/site-packages/rest_framework/views.py", line 469, in handle_exception
    self.raise_uncaught_exception(exc)
  File "/usr/local/lib/python3.11/site-packages/rest_framework/views.py", line 480, in raise_uncaught_exception
    raise exc
  File "/usr/local/lib/python3.11/site-packages/rest_framework/views.py", line 506, in dispatch
    response = handler(request, *args, **kwargs)
               ^^^^^^^^^^^^^^^^^^^^^^^^^^^^^^^^^
  File "/home/accounts/views.py", line 57, in oauth_callback
    return redirect('home:home')
           ^^^^^^^^
NameError: name 'redirect' is not defined
WARNING 2025-01-08 14:10:22,678 Forbidden: /api/user/online-users/
WARNING 2025-01-08 14:10:22,678 Forbidden: /api/user/online-users/
WARNING 2025-01-08 14:15:40,608 Forbidden: /api/oauth/logout/
WARNING 2025-01-08 14:15:40,608 Forbidden: /api/oauth/logout/
